[2022-09-19 18:29:28] 【任务id】：sqRG1XMrjJ5ONHnK; 【ERROR】：Traceback (most recent call last):
  File "F:\Python311\Lib\site-packages\urllib3\connectionpool.py", line 700, in urlopen
    self._prepare_proxy(conn)
    ^^^^^^^^^^^^^^^^^^^^^^^^^
  File "F:\Python311\Lib\site-packages\urllib3\connectionpool.py", line 994, in _prepare_proxy
    conn.connect()
    ^^^^^^^^^^^^^^
  File "F:\Python311\Lib\site-packages\urllib3\connection.py", line 364, in connect
    self.sock = conn = self._connect_tls_proxy(hostname, conn)
                       ^^^^^^^^^^^^^^^^^^^^^^^^^^^^^^^^^^^^^^^
  File "F:\Python311\Lib\site-packages\urllib3\connection.py", line 499, in _connect_tls_proxy
    socket = ssl_wrap_socket(
             ^^^^^^^^^^^^^^^^
  File "F:\Python311\Lib\site-packages\urllib3\util\ssl_.py", line 453, in ssl_wrap_socket
    ssl_sock = _ssl_wrap_socket_impl(sock, context, tls_in_tls)
               ^^^^^^^^^^^^^^^^^^^^^^^^^^^^^^^^^^^^^^^^^^^^^^^^
  File "F:\Python311\Lib\site-packages\urllib3\util\ssl_.py", line 495, in _ssl_wrap_socket_impl
    return ssl_context.wrap_socket(sock)
           ^^^^^^^^^^^^^^^^^^^^^^^^^^^^^
  File "F:\Python311\Lib\ssl.py", line 516, in wrap_socket
    return self.sslsocket_class._create(
           ^^^^^^^^^^^^^^^^^^^^^^^^^^^^^
  File "F:\Python311\Lib\ssl.py", line 1074, in _create
    self.do_handshake()
    ^^^^^^^^^^^^^^^^^^^
  File "F:\Python311\Lib\ssl.py", line 1345, in do_handshake
    self._sslobj.do_handshake()
    ^^^^^^^^^^^^^^^^^^^^^^^^^^^
TimeoutError: _ssl.c:975: The handshake operation timed out

During handling of the above exception, another exception occurred:

Traceback (most recent call last):
  File "F:\Python311\Lib\site-packages\requests\adapters.py", line 489, in send
    resp = conn.urlopen(
           ^^^^^^^^^^^^^
  File "F:\Python311\Lib\site-packages\urllib3\connectionpool.py", line 785, in urlopen
    retries = retries.increment(
              ^^^^^^^^^^^^^^^^^^
  File "F:\Python311\Lib\site-packages\urllib3\util\retry.py", line 592, in increment
    raise MaxRetryError(_pool, url, error or ResponseError(cause))
    ^^^^^^^^^^^^^^^^^^^^^^^^^^^^^^^^^^^^^^^^^^^^^^^^^^^^^^^^^^^^^^
urllib3.exceptions.MaxRetryError: HTTPSConnectionPool(host='feature.kingdee.com', port=1026): Max retries exceeded with url: /feature_sit_hr/monitor/eye/logQuery (Caused by ProxyError('Cannot connect to proxy.', TimeoutError('_ssl.c:975: The handshake operation timed out')))

During handling of the above exception, another exception occurred:

Traceback (most recent call last):
  File "D:\安全\自研工具\seninfo\MScan\MScan\scan_test3.py", line 101, in mscan
    res = requests.post(self.url,verify=False,json=payload,headers=headers,timeout=10)
          ^^^^^^^^^^^^^^^^^^^^^^^^^^^^^^^^^^^^^^^^^^^^^^^^^^^^^^^^^^^^^^^^^^^^^^^^^^^^
  File "F:\Python311\Lib\site-packages\requests\api.py", line 115, in post
    return request("post", url, data=data, json=json, **kwargs)
           ^^^^^^^^^^^^^^^^^^^^^^^^^^^^^^^^^^^^^^^^^^^^^^^^^^^^
  File "F:\Python311\Lib\site-packages\requests\api.py", line 59, in request
    return session.request(method=method, url=url, **kwargs)
           ^^^^^^^^^^^^^^^^^^^^^^^^^^^^^^^^^^^^^^^^^^^^^^^^^
  File "F:\Python311\Lib\site-packages\requests\sessions.py", line 587, in request
    resp = self.send(prep, **send_kwargs)
           ^^^^^^^^^^^^^^^^^^^^^^^^^^^^^^
  File "F:\Python311\Lib\site-packages\requests\sessions.py", line 701, in send
    r = adapter.send(request, **kwargs)
        ^^^^^^^^^^^^^^^^^^^^^^^^^^^^^^^
  File "F:\Python311\Lib\site-packages\requests\adapters.py", line 559, in send
    raise ProxyError(e, request=request)
    ^^^^^^^^^^^^^^^^^^^^^^^^^^^^^^^^^^^^
requests.exceptions.ProxyError: HTTPSConnectionPool(host='feature.kingdee.com', port=1026): Max retries exceeded with url: /feature_sit_hr/monitor/eye/logQuery (Caused by ProxyError('Cannot connect to proxy.', TimeoutError('_ssl.c:975: The handshake operation timed out')))
